Workbook
Name OLE_LINK1: Cuestionario!$B$53

Sheet Cuestionario
D11: TEST DE BELBIN
B20: INSTRUCCIONES
B22: En cada una de las secciones, reparta un total de diez puntos entre las oraciones que crea que mejor describen su conducta. Estos diez puntos se pueden repartir entre varias oraciones. En los casos extremos, puede que se distribuyan equitativamente entre todas las oraciones, o se puedan otorgar los diez puntos a una única oración.
B33: SECCIÓN I: CÓMO CREO QUE PUEDO CONTRIBUIR AL GRUPO
B39: Puntos | C39: Nº de pregunta | D39: Descripción de la Conducta
B40: 10 | C40: 10 | D40: Creo que identifico rápidamente y aprovecho las oportunidades nuevas
C41: 11 | D41: Trabajo muy bien con una amplia gama de gente distinta
C42: 12 | D42: Tener ideas es una de mis cualidades innatas
C43: 13 | D43: Tengo habilidad para hacer hablar a las personas y hacer que se expresen cuando detecto que pueden aportar algo de valor a los objetivos del grupo.
C44: 14 | D44: Pueden confiar en que acabaré cualquier tarea que esté haciendo. Por lo tanto, mi capacidad de llevara acabo las cosas que tienen mucho que ver con mi efectividad personal.
C45: 15 | D45: Estoy dispuesto a enfrentarme a la impopularidad temporal, especialmente si ello conduce a resultados que al final merecen la pena.
C46: 16 | D46: Me doy cuenta rápidamente de los planes e ideas que pueden funcionar en una situación particular.
C47: 17 | D47: Soy capaz de ofrecer un argumento razonado para una línea de actuación alternativa, sin que dé lugar a interpretaciones sesgadas o prejuicios.
B53: SECCIÓN II: SI TENGO ALGÚN DEFECTO EN EL TRABAJO EN EQUIPO PUEDE SER:
B55: Puntos | C55: Nº de pregunta | D55: Descripción de la conducta
B56: 10 | C56: 20 | D56: A no ser que las reuniones estén claramente estructuradas, bien controladas y en general dirigidas eficazmente, no me siento tranquilo.
C57: 21 | D57: Tiendo a ser demasiado generoso con aquellos que tienen un punto de vista válido que no ha sido escuchado/publicado debidamente.
C58: 22 | D58: Tiendo a hablar demasiado una vez que el grupo pasa a un tema nuevo
C59: 23 | D59: Mi objetivo y punto de vista racional hace que me sea difícil unirme fácilmente y con entusiasmo a los compañeros.
C60: 24 | D60: A veces me ven como una persona enérgica y autoritaria cuando tengo que tratar temas importantes que quieren una acción.
C61: 25 | D61: Me resulta difícil dirigir “de frente”, quizás porque soy demasiado sensible y susceptible al clima del grupo.
C62: 26 | D62: Soy propenso a involucrarme demasiado y a “enredarme” en ideas que se me ocurren. Por ello, tiendo a perder el hilo de otras cosas que están ocurriendo en el grupo.
C63: 27 | D63: Tiendo a preocuparme demasiado por los detalles y por la posibilidad de que las cosas no vayan bien debido a una planificación insuficiente.
B65: SECCIÓN III: CUANDO ESTOY METIDO EN UN PROYECTO CON OTRAS PERSONAS
B68: Puntos | C68: Nº de pregunta | D68: Descripción de la conducta
B69: 10 | C69: 30 | D69: Tengo facilidad para influir en las personas sin impresionarlas ni obligarlas.
C70: 31 | D70: La atención la pongo en los detalles, el seguimiento concienzudo y la vigilancia general evitan que se cometan errores tontos y omisiones que podrían comprometer un buen resultado.
C71: 32 | D71: Muchas veces presiono para que se hagan cosas para asegurarme de que no se pierde el tiempo o se pierden de vista los objetivos principales de las reuniones.
C72: 33 | D72: Se puede contar conmigo para aportar ideas muy originales en actividades de resolución de problemas.
C73: 34 | D73: Siempre estoy dispuesto a apoyar una buena sugerencia en pro del interés común.
C74: 35 | D74: Soy capaz de ver rápidamente las posibilidades de nuevas ideas y desarrollos.
C75: 36 | D75: Creo que mi capacidad de dar juicios razonados y serenos es valorada por los demás ya que ayuda a tomar decisiones equilibradas.
C76: 37 | D76: Se puede contar conmigo para asegurar que todas las tareas fundamentales están organizadas y repartidas entre los miembros del grupo.
B79: SECCIÓN IV: MI ENFOQUE HABITUAL AL TRABAJAR EN EQUIPO ES:
B81: Puntos | C81: Nº de pregunta | D81: Descripción de la conducta
B82: 10 | C82: 40 | D82: Tengo un callado interés en conocer mejor a mis compañeros.
C83: 41 | D83: No soy reacio a desafiar los puntos de vista de los demás o a mantener un punto de vista minoritario.
C84: 42 | D84: Tengo habilidad para plantear argumentos razonados y una línea de pensamiento rigurosa para poner a prueba las propuestas nuevas y detectar sus posibles debilidades.
C85: 43 | D85: Tengo talento para hacer que las cosas funcionen cuando hay que poner en práctica un plan.
C86: 44 | D86: Prefiero evitar lo obvio y buscar soluciones innovadoras, creativas e inesperadas.
...

Sheet Respuestas
B2: HOJA DE RESPUESTAS DEL INVENTARIO DE DIRECCIÓN DE GRUPOS
B5: INSTRUCCIONES
B8: Traslade el número de puntos que asignó a cada afirmación del cuestionario a la casilla “Puntos” (Pts) situada más abajo.
B12: SECCIÓN | C12: IMPULSOR | E12: COORDINADOR | G12: IMPLEMENTADOR | I12: CEREBRO | K12: INV. RECURSOS | M12: MONITOR-EVALUADOR | O12: COHESIONADOR | Q12: FINALIZADOR
C14: Nº | D14: Puntos | E14: Nº | F14: Puntos | G14: Nº | H14: Pts. | I14: Nº | J14: Pts. | K14: Nº | L14: Pts. | M14: Nº | N14: Pts. | O14: Nº | P14: Pts. | Q14: Nº | R14: Pts.
B15: I | C15: 16 | D15: =Cuestionario!B46 | E15: 13 | F15: =Cuestionario!B43 | G15: 15 | H15: =Cuestionario!B45 | I15: 12 | J15: =Cuestionario!B42 | K15: 10 | L15: =Cuestionario!B40 -> 10 | M15: 17 | N15: =Cuestionario!B47 | O15: 11 | P15: =Cuestionario!B41 | Q15: 14 | R15: =Cuestionario!B44
B16: II | C16: 20 | D16: =Cuestionario!B56 -> 10 | E16: 21 | F16: =Cuestionario!B57 | G16: 24 | H16: =Cuestionario!B60 | I16: 26 | J16: =Cuestionario!B62 | K16: 22 | L16: =Cuestionario!B58 | M16: 23 | N16: =Cuestionario!B59 | O16: 25 | P16: =Cuestionario!B61 | Q16: 27 | R16: =Cuestionario!B63
B17: III | C17: 37 | D17: =Cuestionario!B76 | E17: 30 | F17: =Cuestionario!B69 -> 10 | G17: 32 | H17: =Cuestionario!B71 | I17: 33 | J17: =Cuestionario!B72 | K17: 35 | L17: =Cuestionario!B74 | M17: 36 | N17: =Cuestionario!B75 | O17: 34 | P17: =Cuestionario!B73 | Q17: 31 | R17: =Cuestionario!B70
B18: IV | C18: 43 | D18: =Cuestionario!B85 | E18: 47 | F18: =Cuestionario!B89 | G18: 41 | H18: =Cuestionario!B83 | I18: 44 | J18: =Cuestionario!B86 | K18: 46 | L18: =Cuestionario!B88 | M18: 42 | N18: =Cuestionario!B84 | O18: 40 | P18: =Cuestionario!B82 -> 10 | Q18: 45 | R18: =Cuestionario!B87
B19: V | C19: 51 | D19: =Cuestionario!B96 | E19: 55 | F19: =Cuestionario!B100 | G19: 53 | H19: =Cuestionario!B98 | I19: 57 | J19: =Cuestionario!B102 | K19: 54 | L19: =Cuestionario!B99 | M19: 50 | N19: =Cuestionario!B95 -> 10 | O19: 52 | P19: =Cuestionario!B97 | Q19: 56 | R19: =Cuestionario!B101
B20: VI | C20: 65 | D20: =Cuestionario!B116 | E20: 62 | F20: =Cuestionario!B113 | G20: 66 | H20: =Cuestionario!B117 | I20: 60 | J20: =Cuestionario!B111 -> 10 | K20: 67 | L20: =Cuestionario!B118 | M20: 64 | N20: =Cuestionario!B115 | O20: 61 | P20: =Cuestionario!B112 | Q20: 63 | R20: =Cuestionario!B114
B21: VII | C21: 74 | D21: =Cuestionario!B132 | E21: 76 | F21: =Cuestionario!B134 | G21: 70 | H21: =Cuestionario!B128 -> 10 | I21: 75 | J21: =Cuestionario!B133 | K21: 73 | L21: =Cuestionario!B131 | M21: 71 | N21: =Cuestionario!B129 | O21: 77 | P21: =Cuestionario!B135 | Q21: 72 | R21: =Cuestionario!B130
B22: TOTAL | D22: 0 | F22: 0 | H22: =SUM(H15:H21) -> 10 | J22: =SUM(J15:J21) -> 10 | L22: =SUM(L15:L21) -> 10 | N22: =SUM(N15:N21) -> 10 | P22: =SUM(P15:P21) -> 10 | R22: =SUM(R15:R21) -> 0

Sheet Gráfico
C4: Resultado
B5: Impulsor | C5: =Respuestas!D22 -> 0
B6: Coordinador | C6: =Respuestas!F22 -> 0
B7: Implementador | C7: =Respuestas!H22 -> 10
B8: Cerebro | C8: =Respuestas!J22 -> 10
B9: Inv. Recursos | C9: =Respuestas!L22 -> 10
B10: Monitor-evaluador | C10: =Respuestas!N22 -> 10
B11: Cohesionador | C11: =Respuestas!P22 -> 10
B12: Finalizador | C12: =Respuestas!R22 -> 0

Sheet Resultados
B3: COMPORTAMIENTO OBSERVADO EN LOS ROLES DEL EQUIPO
B5: CEREBRO (Hombre de ideas) | C5: CE
B7: -Inicia nuevas ideas
B8: -presenta propuestas
B9: -Ofrece una profundización de líneas de acción ya acordadas
B10: -Facilita nuevas estrategias
B11: -Se preocupa de las principales cuestiones
B12: -Busca avances (nuevos caminos) en el enfoque
B15: MONITOR-EVALUADOR (Crítico) | C15: ME
B17: -Analiza y evalúa problemas
B18: -Interpreta situaciones y problemas
B19: -Evalúa las ideas y sugerencias de los demás
B20: -Interpreta un material complejo (escrito u oral)
B21: -Aclara los puntos oscuros
B22: -Ve las complicaciones e inconvenientes de las distintas propuestas
B23: -Juzga de forma desapasionada
B24: -Critica a los demás (“Abogado del diablo”)
B27: COORDINADOR (Nexo) | C27: CO
B29: - Controla el progreso del grupo
B31: - Facilita la toma de decisiones de otros miembros
B32: - Asegura esfuerzos centrados y orientados a los objetivos
B33: - Reconoce los puntos fuertes y débiles de diferentes miembros (los apoya o les quita importancia)
B34: - Determina el tiempo adecuado para las intervenciones (distribución del tiempo)
B35: - Mantiene una opinión equilibrada (permanece atrás y objetivo)
B36: - Comunica con efectividad
B37: - Inspira entusiasmo a los demás
B38: - Confía en los demás
B39: - Es decisivo
B40: - “Lo suficientemente tolerante para escuchar, lo suficientemente firme como para rechazar un consejo”
B41: - Funciona como centro neurálgico
B44: IMPULSOR (Presidente no oficial) | C44: IS
B46: - Busca y encuentra modelos en las discusiones
B47: - Impone pautas en las discusiones
B48: - Articula los sentimientos del grupo
B49: - Expresa el veredicto del equipo
B50: - Establece los papeles, obligaciones y tareas de los otros
B51: - Conforma los objetivos y responsabilidades de los otros
B52: - Se preocupa de sus propias prioridades
B53: - Muestra un sentido de perspectiva
B54: - Está ya con entusiasmo y energía
...
